2020-01-15 12:06:39.393311
Traceback (most recent call last):
  File "D:\CMS\New folder\tripude_cms\venv\lib\site-packages\django\db\backends\base\base.py", line 220, in ensure_connection
    self.connect()
  File "D:\CMS\New folder\tripude_cms\venv\lib\site-packages\django\utils\asyncio.py", line 26, in inner
    return func(*args, **kwargs)
  File "D:\CMS\New folder\tripude_cms\venv\lib\site-packages\django\db\backends\base\base.py", line 197, in connect
    self.connection = self.get_new_connection(conn_params)
  File "D:\CMS\New folder\tripude_cms\venv\lib\site-packages\django\utils\asyncio.py", line 26, in inner
    return func(*args, **kwargs)
  File "D:\CMS\New folder\tripude_cms\venv\lib\site-packages\django\db\backends\mysql\base.py", line 233, in get_new_connection
    return Database.connect(**conn_params)
  File "D:\CMS\New folder\tripude_cms\venv\lib\site-packages\MySQLdb\__init__.py", line 84, in Connect
    return Connection(*args, **kwargs)
  File "D:\CMS\New folder\tripude_cms\venv\lib\site-packages\MySQLdb\connections.py", line 179, in __init__
    super(Connection, self).__init__(*args, **kwargs2)
MySQLdb._exceptions.OperationalError: (2002, "Can't connect to MySQL server on '3.6.127.100' (10060)")

The above exception was the direct cause of the following exception:

Traceback (most recent call last):
  File "D:\CMS\tirpude_cms\authentication\views.py", line 62, in get_city_district_list
    city_list = list(City.objects.filter(fk_state_id=state_id).values_list("id", "city"))
  File "D:\CMS\New folder\tripude_cms\venv\lib\site-packages\django\db\models\query.py", line 276, in __iter__
    self._fetch_all()
  File "D:\CMS\New folder\tripude_cms\venv\lib\site-packages\django\db\models\query.py", line 1261, in _fetch_all
    self._result_cache = list(self._iterable_class(self))
  File "D:\CMS\New folder\tripude_cms\venv\lib\site-packages\django\db\models\query.py", line 146, in __iter__
    return compiler.results_iter(tuple_expected=True, chunked_fetch=self.chunked_fetch, chunk_size=self.chunk_size)
  File "D:\CMS\New folder\tripude_cms\venv\lib\site-packages\django\db\models\sql\compiler.py", line 1089, in results_iter
    results = self.execute_sql(MULTI, chunked_fetch=chunked_fetch, chunk_size=chunk_size)
  File "D:\CMS\New folder\tripude_cms\venv\lib\site-packages\django\db\models\sql\compiler.py", line 1135, in execute_sql
    cursor = self.connection.cursor()
  File "D:\CMS\New folder\tripude_cms\venv\lib\site-packages\django\utils\asyncio.py", line 26, in inner
    return func(*args, **kwargs)
  File "D:\CMS\New folder\tripude_cms\venv\lib\site-packages\django\db\backends\base\base.py", line 260, in cursor
    return self._cursor()
  File "D:\CMS\New folder\tripude_cms\venv\lib\site-packages\django\db\backends\base\base.py", line 236, in _cursor
    self.ensure_connection()
  File "D:\CMS\New folder\tripude_cms\venv\lib\site-packages\django\utils\asyncio.py", line 26, in inner
    return func(*args, **kwargs)
  File "D:\CMS\New folder\tripude_cms\venv\lib\site-packages\django\db\backends\base\base.py", line 220, in ensure_connection
    self.connect()
  File "D:\CMS\New folder\tripude_cms\venv\lib\site-packages\django\db\utils.py", line 90, in __exit__
    raise dj_exc_value.with_traceback(traceback) from exc_value
  File "D:\CMS\New folder\tripude_cms\venv\lib\site-packages\django\db\backends\base\base.py", line 220, in ensure_connection
    self.connect()
  File "D:\CMS\New folder\tripude_cms\venv\lib\site-packages\django\utils\asyncio.py", line 26, in inner
    return func(*args, **kwargs)
  File "D:\CMS\New folder\tripude_cms\venv\lib\site-packages\django\db\backends\base\base.py", line 197, in connect
    self.connection = self.get_new_connection(conn_params)
  File "D:\CMS\New folder\tripude_cms\venv\lib\site-packages\django\utils\asyncio.py", line 26, in inner
    return func(*args, **kwargs)
  File "D:\CMS\New folder\tripude_cms\venv\lib\site-packages\django\db\backends\mysql\base.py", line 233, in get_new_connection
    return Database.connect(**conn_params)
  File "D:\CMS\New folder\tripude_cms\venv\lib\site-packages\MySQLdb\__init__.py", line 84, in Connect
    return Connection(*args, **kwargs)
  File "D:\CMS\New folder\tripude_cms\venv\lib\site-packages\MySQLdb\connections.py", line 179, in __init__
    super(Connection, self).__init__(*args, **kwargs2)
django.db.utils.OperationalError: (2002, "Can't connect to MySQL server on '3.6.127.100' (10060)")


