2020-01-10 11:53:23.247700
Traceback (most recent call last):
  File "D:\GIT CMS TIRPUDE\venv\lib\site-packages\django\db\backends\utils.py", line 86, in _execute
    return self.cursor.execute(sql, params)
  File "D:\GIT CMS TIRPUDE\venv\lib\site-packages\django\db\backends\mysql\base.py", line 74, in execute
    return self.cursor.execute(query, args)
  File "D:\GIT CMS TIRPUDE\venv\lib\site-packages\MySQLdb\cursors.py", line 209, in execute
    res = self._query(query)
  File "D:\GIT CMS TIRPUDE\venv\lib\site-packages\MySQLdb\cursors.py", line 315, in _query
    db.query(q)
  File "D:\GIT CMS TIRPUDE\venv\lib\site-packages\MySQLdb\connections.py", line 239, in query
    _mysql.connection.query(self, query)
MySQLdb._exceptions.IntegrityError: (1451, 'Cannot delete or update a parent row: a foreign key constraint fails (`tirpude_cms`.`aptitude_aptitudesession`, CONSTRAINT `aptitude_aptitudeses_fk_user_info_id_b01abb8b_fk_authentic` FOREIGN KEY (`fk_user_info_id`) REFERENCES `authentication_userinfo` (`id`))')

The above exception was the direct cause of the following exception:

Traceback (most recent call last):
  File "D:\GIT CMS TIRPUDE\authenticate_user\views.py", line 154, in delete_register_request
    user_info_detail_obj.delete()
  File "D:\GIT CMS TIRPUDE\venv\lib\site-packages\django\db\models\base.py", line 937, in delete
    return collector.delete()
  File "D:\GIT CMS TIRPUDE\venv\lib\site-packages\django\db\models\deletion.py", line 332, in delete
    count = query.delete_batch(pk_list, self.using)
  File "D:\GIT CMS TIRPUDE\venv\lib\site-packages\django\db\models\sql\subqueries.py", line 41, in delete_batch
    num_deleted += self.do_query(self.get_meta().db_table, self.where, using=using)
  File "D:\GIT CMS TIRPUDE\venv\lib\site-packages\django\db\models\sql\subqueries.py", line 24, in do_query
    cursor = self.get_compiler(using).execute_sql(CURSOR)
  File "D:\GIT CMS TIRPUDE\venv\lib\site-packages\django\db\models\sql\compiler.py", line 1137, in execute_sql
    cursor.execute(sql, params)
  File "D:\GIT CMS TIRPUDE\venv\lib\site-packages\django\db\backends\utils.py", line 100, in execute
    return super().execute(sql, params)
  File "D:\GIT CMS TIRPUDE\venv\lib\site-packages\django\db\backends\utils.py", line 68, in execute
    return self._execute_with_wrappers(sql, params, many=False, executor=self._execute)
  File "D:\GIT CMS TIRPUDE\venv\lib\site-packages\django\db\backends\utils.py", line 77, in _execute_with_wrappers
    return executor(sql, params, many, context)
  File "D:\GIT CMS TIRPUDE\venv\lib\site-packages\django\db\backends\utils.py", line 86, in _execute
    return self.cursor.execute(sql, params)
  File "D:\GIT CMS TIRPUDE\venv\lib\site-packages\django\db\utils.py", line 90, in __exit__
    raise dj_exc_value.with_traceback(traceback) from exc_value
  File "D:\GIT CMS TIRPUDE\venv\lib\site-packages\django\db\backends\utils.py", line 86, in _execute
    return self.cursor.execute(sql, params)
  File "D:\GIT CMS TIRPUDE\venv\lib\site-packages\django\db\backends\mysql\base.py", line 74, in execute
    return self.cursor.execute(query, args)
  File "D:\GIT CMS TIRPUDE\venv\lib\site-packages\MySQLdb\cursors.py", line 209, in execute
    res = self._query(query)
  File "D:\GIT CMS TIRPUDE\venv\lib\site-packages\MySQLdb\cursors.py", line 315, in _query
    db.query(q)
  File "D:\GIT CMS TIRPUDE\venv\lib\site-packages\MySQLdb\connections.py", line 239, in query
    _mysql.connection.query(self, query)
django.db.utils.IntegrityError: (1451, 'Cannot delete or update a parent row: a foreign key constraint fails (`tirpude_cms`.`aptitude_aptitudesession`, CONSTRAINT `aptitude_aptitudeses_fk_user_info_id_b01abb8b_fk_authentic` FOREIGN KEY (`fk_user_info_id`) REFERENCES `authentication_userinfo` (`id`))')


2020-01-10 12:06:32.961499
Traceback (most recent call last):
  File "D:\GIT CMS TIRPUDE\venv\lib\site-packages\django\db\models\fields\__init__.py", line 1768, in get_prep_value
    return int(value)
ValueError: invalid literal for int() with base 10: ''

The above exception was the direct cause of the following exception:

Traceback (most recent call last):
  File "D:\GIT CMS TIRPUDE\authentication\views.py", line 62, in get_city_district_list
    city_list = list(City.objects.filter(fk_state_id=state_id).values_list("id", "city"))
  File "D:\GIT CMS TIRPUDE\venv\lib\site-packages\django\db\models\manager.py", line 82, in manager_method
    return getattr(self.get_queryset(), name)(*args, **kwargs)
  File "D:\GIT CMS TIRPUDE\venv\lib\site-packages\django\db\models\query.py", line 904, in filter
    return self._filter_or_exclude(False, *args, **kwargs)
  File "D:\GIT CMS TIRPUDE\venv\lib\site-packages\django\db\models\query.py", line 923, in _filter_or_exclude
    clone.query.add_q(Q(*args, **kwargs))
  File "D:\GIT CMS TIRPUDE\venv\lib\site-packages\django\db\models\sql\query.py", line 1340, in add_q
    clause, _ = self._add_q(q_object, self.used_aliases)
  File "D:\GIT CMS TIRPUDE\venv\lib\site-packages\django\db\models\sql\query.py", line 1371, in _add_q
    check_filterable=check_filterable,
  File "D:\GIT CMS TIRPUDE\venv\lib\site-packages\django\db\models\sql\query.py", line 1301, in build_filter
    condition = self.build_lookup(lookups, col, value)
  File "D:\GIT CMS TIRPUDE\venv\lib\site-packages\django\db\models\sql\query.py", line 1155, in build_lookup
    lookup = lookup_class(lhs, rhs)
  File "D:\GIT CMS TIRPUDE\venv\lib\site-packages\django\db\models\lookups.py", line 22, in __init__
    self.rhs = self.get_prep_lookup()
  File "D:\GIT CMS TIRPUDE\venv\lib\site-packages\django\db\models\fields\related_lookups.py", line 115, in get_prep_lookup
    self.rhs = target_field.get_prep_value(self.rhs)
  File "D:\GIT CMS TIRPUDE\venv\lib\site-packages\django\db\models\fields\__init__.py", line 1772, in get_prep_value
    ) from e
ValueError: Field 'id' expected a number but got ''.



2020-01-10 12:06:32.962501
Traceback (most recent call last):
  File "D:\GIT CMS TIRPUDE\venv\lib\site-packages\django\db\models\fields\__init__.py", line 1768, in get_prep_value
    return int(value)
ValueError: invalid literal for int() with base 10: ''

The above exception was the direct cause of the following exception:

Traceback (most recent call last):
  File "D:\GIT CMS TIRPUDE\authentication\views.py", line 62, in get_city_district_list
    city_list = list(City.objects.filter(fk_state_id=state_id).values_list("id", "city"))
  File "D:\GIT CMS TIRPUDE\venv\lib\site-packages\django\db\models\manager.py", line 82, in manager_method
    return getattr(self.get_queryset(), name)(*args, **kwargs)
  File "D:\GIT CMS TIRPUDE\venv\lib\site-packages\django\db\models\query.py", line 904, in filter
    return self._filter_or_exclude(False, *args, **kwargs)
  File "D:\GIT CMS TIRPUDE\venv\lib\site-packages\django\db\models\query.py", line 923, in _filter_or_exclude
    clone.query.add_q(Q(*args, **kwargs))
  File "D:\GIT CMS TIRPUDE\venv\lib\site-packages\django\db\models\sql\query.py", line 1340, in add_q
    clause, _ = self._add_q(q_object, self.used_aliases)
  File "D:\GIT CMS TIRPUDE\venv\lib\site-packages\django\db\models\sql\query.py", line 1371, in _add_q
    check_filterable=check_filterable,
  File "D:\GIT CMS TIRPUDE\venv\lib\site-packages\django\db\models\sql\query.py", line 1301, in build_filter
    condition = self.build_lookup(lookups, col, value)
  File "D:\GIT CMS TIRPUDE\venv\lib\site-packages\django\db\models\sql\query.py", line 1155, in build_lookup
    lookup = lookup_class(lhs, rhs)
  File "D:\GIT CMS TIRPUDE\venv\lib\site-packages\django\db\models\lookups.py", line 22, in __init__
    self.rhs = self.get_prep_lookup()
  File "D:\GIT CMS TIRPUDE\venv\lib\site-packages\django\db\models\fields\related_lookups.py", line 115, in get_prep_lookup
    self.rhs = target_field.get_prep_value(self.rhs)
  File "D:\GIT CMS TIRPUDE\venv\lib\site-packages\django\db\models\fields\__init__.py", line 1772, in get_prep_value
    ) from e
ValueError: Field 'id' expected a number but got ''.


2020-01-10 12:06:32.962501
Traceback (most recent call last):
  File "D:\GIT CMS TIRPUDE\venv\lib\site-packages\django\db\models\fields\__init__.py", line 1768, in get_prep_value
    return int(value)
ValueError: invalid literal for int() with base 10: ''

The above exception was the direct cause of the following exception:

Traceback (most recent call last):
  File "D:\GIT CMS TIRPUDE\authentication\views.py", line 98, in get_stream_or_field_list
    StreamOrField.objects.filter(fk_twelveth_or_diploma_id=twelveth_or_diploma).values_list("id",
  File "D:\GIT CMS TIRPUDE\venv\lib\site-packages\django\db\models\manager.py", line 82, in manager_method
    return getattr(self.get_queryset(), name)(*args, **kwargs)
  File "D:\GIT CMS TIRPUDE\venv\lib\site-packages\django\db\models\query.py", line 904, in filter
    return self._filter_or_exclude(False, *args, **kwargs)
  File "D:\GIT CMS TIRPUDE\venv\lib\site-packages\django\db\models\query.py", line 923, in _filter_or_exclude
    clone.query.add_q(Q(*args, **kwargs))
  File "D:\GIT CMS TIRPUDE\venv\lib\site-packages\django\db\models\sql\query.py", line 1340, in add_q
    clause, _ = self._add_q(q_object, self.used_aliases)
  File "D:\GIT CMS TIRPUDE\venv\lib\site-packages\django\db\models\sql\query.py", line 1371, in _add_q
    check_filterable=check_filterable,
  File "D:\GIT CMS TIRPUDE\venv\lib\site-packages\django\db\models\sql\query.py", line 1301, in build_filter
    condition = self.build_lookup(lookups, col, value)
  File "D:\GIT CMS TIRPUDE\venv\lib\site-packages\django\db\models\sql\query.py", line 1155, in build_lookup
    lookup = lookup_class(lhs, rhs)
  File "D:\GIT CMS TIRPUDE\venv\lib\site-packages\django\db\models\lookups.py", line 22, in __init__
    self.rhs = self.get_prep_lookup()
  File "D:\GIT CMS TIRPUDE\venv\lib\site-packages\django\db\models\fields\related_lookups.py", line 115, in get_prep_lookup
    self.rhs = target_field.get_prep_value(self.rhs)
  File "D:\GIT CMS TIRPUDE\venv\lib\site-packages\django\db\models\fields\__init__.py", line 1772, in get_prep_value
    ) from e
ValueError: Field 'id' expected a number but got ''.


2020-01-10 12:06:32.961499
Traceback (most recent call last):
  File "D:\GIT CMS TIRPUDE\venv\lib\site-packages\django\db\models\fields\__init__.py", line 1768, in get_prep_value
    return int(value)
ValueError: invalid literal for int() with base 10: ''

The above exception was the direct cause of the following exception:

Traceback (most recent call last):
  File "D:\GIT CMS TIRPUDE\authentication\views.py", line 117, in get_degree_stream_or_field_list
    DegreeStreamOrField.objects.filter(fk_degree_id=degree).values_list("id", "stream_or_field_name"))
  File "D:\GIT CMS TIRPUDE\venv\lib\site-packages\django\db\models\manager.py", line 82, in manager_method
    return getattr(self.get_queryset(), name)(*args, **kwargs)
  File "D:\GIT CMS TIRPUDE\venv\lib\site-packages\django\db\models\query.py", line 904, in filter
    return self._filter_or_exclude(False, *args, **kwargs)
  File "D:\GIT CMS TIRPUDE\venv\lib\site-packages\django\db\models\query.py", line 923, in _filter_or_exclude
    clone.query.add_q(Q(*args, **kwargs))
  File "D:\GIT CMS TIRPUDE\venv\lib\site-packages\django\db\models\sql\query.py", line 1340, in add_q
    clause, _ = self._add_q(q_object, self.used_aliases)
  File "D:\GIT CMS TIRPUDE\venv\lib\site-packages\django\db\models\sql\query.py", line 1371, in _add_q
    check_filterable=check_filterable,
  File "D:\GIT CMS TIRPUDE\venv\lib\site-packages\django\db\models\sql\query.py", line 1301, in build_filter
    condition = self.build_lookup(lookups, col, value)
  File "D:\GIT CMS TIRPUDE\venv\lib\site-packages\django\db\models\sql\query.py", line 1155, in build_lookup
    lookup = lookup_class(lhs, rhs)
  File "D:\GIT CMS TIRPUDE\venv\lib\site-packages\django\db\models\lookups.py", line 22, in __init__
    self.rhs = self.get_prep_lookup()
  File "D:\GIT CMS TIRPUDE\venv\lib\site-packages\django\db\models\fields\related_lookups.py", line 115, in get_prep_lookup
    self.rhs = target_field.get_prep_value(self.rhs)
  File "D:\GIT CMS TIRPUDE\venv\lib\site-packages\django\db\models\fields\__init__.py", line 1772, in get_prep_value
    ) from e
ValueError: Field 'id' expected a number but got ''.


2020-01-13 13:03:18.935174
Traceback (most recent call last):
  File "D:\GIT CMS TIRPUDE\venv\lib\site-packages\django\db\backends\utils.py", line 86, in _execute
    return self.cursor.execute(sql, params)
  File "D:\GIT CMS TIRPUDE\venv\lib\site-packages\django\db\backends\mysql\base.py", line 74, in execute
    return self.cursor.execute(query, args)
  File "D:\GIT CMS TIRPUDE\venv\lib\site-packages\MySQLdb\cursors.py", line 209, in execute
    res = self._query(query)
  File "D:\GIT CMS TIRPUDE\venv\lib\site-packages\MySQLdb\cursors.py", line 315, in _query
    db.query(q)
  File "D:\GIT CMS TIRPUDE\venv\lib\site-packages\MySQLdb\connections.py", line 239, in query
    _mysql.connection.query(self, query)
MySQLdb._exceptions.OperationalError: (1054, "Unknown column 'authentication_addressdetail.fk_user_info_id' in 'field list'")

The above exception was the direct cause of the following exception:

Traceback (most recent call last):
  File "D:\GIT CMS TIRPUDE\authentication\views.py", line 283, in profile_user
    address_detail_obj = AddressDetail.objects.get(fk_user_info_id=session)
  File "D:\GIT CMS TIRPUDE\venv\lib\site-packages\django\db\models\manager.py", line 82, in manager_method
    return getattr(self.get_queryset(), name)(*args, **kwargs)
  File "D:\GIT CMS TIRPUDE\venv\lib\site-packages\django\db\models\query.py", line 411, in get
    num = len(clone)
  File "D:\GIT CMS TIRPUDE\venv\lib\site-packages\django\db\models\query.py", line 258, in __len__
    self._fetch_all()
  File "D:\GIT CMS TIRPUDE\venv\lib\site-packages\django\db\models\query.py", line 1261, in _fetch_all
    self._result_cache = list(self._iterable_class(self))
  File "D:\GIT CMS TIRPUDE\venv\lib\site-packages\django\db\models\query.py", line 57, in __iter__
    results = compiler.execute_sql(chunked_fetch=self.chunked_fetch, chunk_size=self.chunk_size)
  File "D:\GIT CMS TIRPUDE\venv\lib\site-packages\django\db\models\sql\compiler.py", line 1137, in execute_sql
    cursor.execute(sql, params)
  File "D:\GIT CMS TIRPUDE\venv\lib\site-packages\django\db\backends\utils.py", line 100, in execute
    return super().execute(sql, params)
  File "D:\GIT CMS TIRPUDE\venv\lib\site-packages\django\db\backends\utils.py", line 68, in execute
    return self._execute_with_wrappers(sql, params, many=False, executor=self._execute)
  File "D:\GIT CMS TIRPUDE\venv\lib\site-packages\django\db\backends\utils.py", line 77, in _execute_with_wrappers
    return executor(sql, params, many, context)
  File "D:\GIT CMS TIRPUDE\venv\lib\site-packages\django\db\backends\utils.py", line 86, in _execute
    return self.cursor.execute(sql, params)
  File "D:\GIT CMS TIRPUDE\venv\lib\site-packages\django\db\utils.py", line 90, in __exit__
    raise dj_exc_value.with_traceback(traceback) from exc_value
  File "D:\GIT CMS TIRPUDE\venv\lib\site-packages\django\db\backends\utils.py", line 86, in _execute
    return self.cursor.execute(sql, params)
  File "D:\GIT CMS TIRPUDE\venv\lib\site-packages\django\db\backends\mysql\base.py", line 74, in execute
    return self.cursor.execute(query, args)
  File "D:\GIT CMS TIRPUDE\venv\lib\site-packages\MySQLdb\cursors.py", line 209, in execute
    res = self._query(query)
  File "D:\GIT CMS TIRPUDE\venv\lib\site-packages\MySQLdb\cursors.py", line 315, in _query
    db.query(q)
  File "D:\GIT CMS TIRPUDE\venv\lib\site-packages\MySQLdb\connections.py", line 239, in query
    _mysql.connection.query(self, query)
django.db.utils.OperationalError: (1054, "Unknown column 'authentication_addressdetail.fk_user_info_id' in 'field list'")


2020-01-13 13:11:29.239478
Traceback (most recent call last):
  File "D:\GIT CMS TIRPUDE\venv\lib\site-packages\django\db\backends\utils.py", line 86, in _execute
    return self.cursor.execute(sql, params)
  File "D:\GIT CMS TIRPUDE\venv\lib\site-packages\django\db\backends\mysql\base.py", line 74, in execute
    return self.cursor.execute(query, args)
  File "D:\GIT CMS TIRPUDE\venv\lib\site-packages\MySQLdb\cursors.py", line 209, in execute
    res = self._query(query)
  File "D:\GIT CMS TIRPUDE\venv\lib\site-packages\MySQLdb\cursors.py", line 315, in _query
    db.query(q)
  File "D:\GIT CMS TIRPUDE\venv\lib\site-packages\MySQLdb\connections.py", line 239, in query
    _mysql.connection.query(self, query)
MySQLdb._exceptions.OperationalError: (1054, "Unknown column 'authentication_addressdetail.fk_city_id' in 'field list'")

The above exception was the direct cause of the following exception:

Traceback (most recent call last):
  File "D:\GIT CMS TIRPUDE\authentication\views.py", line 283, in profile_user
    address_detail_obj = AddressDetail.objects.get(fk_user_info_id=session)
  File "D:\GIT CMS TIRPUDE\venv\lib\site-packages\django\db\models\manager.py", line 82, in manager_method
    return getattr(self.get_queryset(), name)(*args, **kwargs)
  File "D:\GIT CMS TIRPUDE\venv\lib\site-packages\django\db\models\query.py", line 411, in get
    num = len(clone)
  File "D:\GIT CMS TIRPUDE\venv\lib\site-packages\django\db\models\query.py", line 258, in __len__
    self._fetch_all()
  File "D:\GIT CMS TIRPUDE\venv\lib\site-packages\django\db\models\query.py", line 1261, in _fetch_all
    self._result_cache = list(self._iterable_class(self))
  File "D:\GIT CMS TIRPUDE\venv\lib\site-packages\django\db\models\query.py", line 57, in __iter__
    results = compiler.execute_sql(chunked_fetch=self.chunked_fetch, chunk_size=self.chunk_size)
  File "D:\GIT CMS TIRPUDE\venv\lib\site-packages\django\db\models\sql\compiler.py", line 1137, in execute_sql
    cursor.execute(sql, params)
  File "D:\GIT CMS TIRPUDE\venv\lib\site-packages\django\db\backends\utils.py", line 100, in execute
    return super().execute(sql, params)
  File "D:\GIT CMS TIRPUDE\venv\lib\site-packages\django\db\backends\utils.py", line 68, in execute
    return self._execute_with_wrappers(sql, params, many=False, executor=self._execute)
  File "D:\GIT CMS TIRPUDE\venv\lib\site-packages\django\db\backends\utils.py", line 77, in _execute_with_wrappers
    return executor(sql, params, many, context)
  File "D:\GIT CMS TIRPUDE\venv\lib\site-packages\django\db\backends\utils.py", line 86, in _execute
    return self.cursor.execute(sql, params)
  File "D:\GIT CMS TIRPUDE\venv\lib\site-packages\django\db\utils.py", line 90, in __exit__
    raise dj_exc_value.with_traceback(traceback) from exc_value
  File "D:\GIT CMS TIRPUDE\venv\lib\site-packages\django\db\backends\utils.py", line 86, in _execute
    return self.cursor.execute(sql, params)
  File "D:\GIT CMS TIRPUDE\venv\lib\site-packages\django\db\backends\mysql\base.py", line 74, in execute
    return self.cursor.execute(query, args)
  File "D:\GIT CMS TIRPUDE\venv\lib\site-packages\MySQLdb\cursors.py", line 209, in execute
    res = self._query(query)
  File "D:\GIT CMS TIRPUDE\venv\lib\site-packages\MySQLdb\cursors.py", line 315, in _query
    db.query(q)
  File "D:\GIT CMS TIRPUDE\venv\lib\site-packages\MySQLdb\connections.py", line 239, in query
    _mysql.connection.query(self, query)
django.db.utils.OperationalError: (1054, "Unknown column 'authentication_addressdetail.fk_city_id' in 'field list'")


2020-01-13 13:13:15.991174
Traceback (most recent call last):
  File "D:\GIT CMS TIRPUDE\venv\lib\site-packages\django\db\backends\utils.py", line 86, in _execute
    return self.cursor.execute(sql, params)
  File "D:\GIT CMS TIRPUDE\venv\lib\site-packages\django\db\backends\mysql\base.py", line 74, in execute
    return self.cursor.execute(query, args)
  File "D:\GIT CMS TIRPUDE\venv\lib\site-packages\MySQLdb\cursors.py", line 209, in execute
    res = self._query(query)
  File "D:\GIT CMS TIRPUDE\venv\lib\site-packages\MySQLdb\cursors.py", line 315, in _query
    db.query(q)
  File "D:\GIT CMS TIRPUDE\venv\lib\site-packages\MySQLdb\connections.py", line 239, in query
    _mysql.connection.query(self, query)
MySQLdb._exceptions.OperationalError: (1054, "Unknown column 'authentication_addressdetail.fk_city_id' in 'field list'")

The above exception was the direct cause of the following exception:

Traceback (most recent call last):
  File "D:\GIT CMS TIRPUDE\authentication\views.py", line 283, in profile_user
    address_detail_obj = AddressDetail.objects.get(fk_user_info_id=session)
  File "D:\GIT CMS TIRPUDE\venv\lib\site-packages\django\db\models\manager.py", line 82, in manager_method
    return getattr(self.get_queryset(), name)(*args, **kwargs)
  File "D:\GIT CMS TIRPUDE\venv\lib\site-packages\django\db\models\query.py", line 411, in get
    num = len(clone)
  File "D:\GIT CMS TIRPUDE\venv\lib\site-packages\django\db\models\query.py", line 258, in __len__
    self._fetch_all()
  File "D:\GIT CMS TIRPUDE\venv\lib\site-packages\django\db\models\query.py", line 1261, in _fetch_all
    self._result_cache = list(self._iterable_class(self))
  File "D:\GIT CMS TIRPUDE\venv\lib\site-packages\django\db\models\query.py", line 57, in __iter__
    results = compiler.execute_sql(chunked_fetch=self.chunked_fetch, chunk_size=self.chunk_size)
  File "D:\GIT CMS TIRPUDE\venv\lib\site-packages\django\db\models\sql\compiler.py", line 1137, in execute_sql
    cursor.execute(sql, params)
  File "D:\GIT CMS TIRPUDE\venv\lib\site-packages\django\db\backends\utils.py", line 100, in execute
    return super().execute(sql, params)
  File "D:\GIT CMS TIRPUDE\venv\lib\site-packages\django\db\backends\utils.py", line 68, in execute
    return self._execute_with_wrappers(sql, params, many=False, executor=self._execute)
  File "D:\GIT CMS TIRPUDE\venv\lib\site-packages\django\db\backends\utils.py", line 77, in _execute_with_wrappers
    return executor(sql, params, many, context)
  File "D:\GIT CMS TIRPUDE\venv\lib\site-packages\django\db\backends\utils.py", line 86, in _execute
    return self.cursor.execute(sql, params)
  File "D:\GIT CMS TIRPUDE\venv\lib\site-packages\django\db\utils.py", line 90, in __exit__
    raise dj_exc_value.with_traceback(traceback) from exc_value
  File "D:\GIT CMS TIRPUDE\venv\lib\site-packages\django\db\backends\utils.py", line 86, in _execute
    return self.cursor.execute(sql, params)
  File "D:\GIT CMS TIRPUDE\venv\lib\site-packages\django\db\backends\mysql\base.py", line 74, in execute
    return self.cursor.execute(query, args)
  File "D:\GIT CMS TIRPUDE\venv\lib\site-packages\MySQLdb\cursors.py", line 209, in execute
    res = self._query(query)
  File "D:\GIT CMS TIRPUDE\venv\lib\site-packages\MySQLdb\cursors.py", line 315, in _query
    db.query(q)
  File "D:\GIT CMS TIRPUDE\venv\lib\site-packages\MySQLdb\connections.py", line 239, in query
    _mysql.connection.query(self, query)
django.db.utils.OperationalError: (1054, "Unknown column 'authentication_addressdetail.fk_city_id' in 'field list'")


2020-01-13 13:15:13.389996
Traceback (most recent call last):
  File "D:\GIT CMS TIRPUDE\venv\lib\site-packages\django\db\backends\utils.py", line 86, in _execute
    return self.cursor.execute(sql, params)
  File "D:\GIT CMS TIRPUDE\venv\lib\site-packages\django\db\backends\mysql\base.py", line 74, in execute
    return self.cursor.execute(query, args)
  File "D:\GIT CMS TIRPUDE\venv\lib\site-packages\MySQLdb\cursors.py", line 209, in execute
    res = self._query(query)
  File "D:\GIT CMS TIRPUDE\venv\lib\site-packages\MySQLdb\cursors.py", line 315, in _query
    db.query(q)
  File "D:\GIT CMS TIRPUDE\venv\lib\site-packages\MySQLdb\connections.py", line 239, in query
    _mysql.connection.query(self, query)
MySQLdb._exceptions.OperationalError: (1054, "Unknown column 'authentication_addressdetail.fk_state_id' in 'field list'")

The above exception was the direct cause of the following exception:

Traceback (most recent call last):
  File "D:\GIT CMS TIRPUDE\authentication\views.py", line 283, in profile_user
    address_detail_obj = AddressDetail.objects.get(fk_user_info_id=session)
  File "D:\GIT CMS TIRPUDE\venv\lib\site-packages\django\db\models\manager.py", line 82, in manager_method
    return getattr(self.get_queryset(), name)(*args, **kwargs)
  File "D:\GIT CMS TIRPUDE\venv\lib\site-packages\django\db\models\query.py", line 411, in get
    num = len(clone)
  File "D:\GIT CMS TIRPUDE\venv\lib\site-packages\django\db\models\query.py", line 258, in __len__
    self._fetch_all()
  File "D:\GIT CMS TIRPUDE\venv\lib\site-packages\django\db\models\query.py", line 1261, in _fetch_all
    self._result_cache = list(self._iterable_class(self))
  File "D:\GIT CMS TIRPUDE\venv\lib\site-packages\django\db\models\query.py", line 57, in __iter__
    results = compiler.execute_sql(chunked_fetch=self.chunked_fetch, chunk_size=self.chunk_size)
  File "D:\GIT CMS TIRPUDE\venv\lib\site-packages\django\db\models\sql\compiler.py", line 1137, in execute_sql
    cursor.execute(sql, params)
  File "D:\GIT CMS TIRPUDE\venv\lib\site-packages\django\db\backends\utils.py", line 100, in execute
    return super().execute(sql, params)
  File "D:\GIT CMS TIRPUDE\venv\lib\site-packages\django\db\backends\utils.py", line 68, in execute
    return self._execute_with_wrappers(sql, params, many=False, executor=self._execute)
  File "D:\GIT CMS TIRPUDE\venv\lib\site-packages\django\db\backends\utils.py", line 77, in _execute_with_wrappers
    return executor(sql, params, many, context)
  File "D:\GIT CMS TIRPUDE\venv\lib\site-packages\django\db\backends\utils.py", line 86, in _execute
    return self.cursor.execute(sql, params)
  File "D:\GIT CMS TIRPUDE\venv\lib\site-packages\django\db\utils.py", line 90, in __exit__
    raise dj_exc_value.with_traceback(traceback) from exc_value
  File "D:\GIT CMS TIRPUDE\venv\lib\site-packages\django\db\backends\utils.py", line 86, in _execute
    return self.cursor.execute(sql, params)
  File "D:\GIT CMS TIRPUDE\venv\lib\site-packages\django\db\backends\mysql\base.py", line 74, in execute
    return self.cursor.execute(query, args)
  File "D:\GIT CMS TIRPUDE\venv\lib\site-packages\MySQLdb\cursors.py", line 209, in execute
    res = self._query(query)
  File "D:\GIT CMS TIRPUDE\venv\lib\site-packages\MySQLdb\cursors.py", line 315, in _query
    db.query(q)
  File "D:\GIT CMS TIRPUDE\venv\lib\site-packages\MySQLdb\connections.py", line 239, in query
    _mysql.connection.query(self, query)
django.db.utils.OperationalError: (1054, "Unknown column 'authentication_addressdetail.fk_state_id' in 'field list'")


2020-01-13 13:17:20.274536
Traceback (most recent call last):
  File "D:\GIT CMS TIRPUDE\venv\lib\site-packages\django\db\backends\utils.py", line 86, in _execute
    return self.cursor.execute(sql, params)
  File "D:\GIT CMS TIRPUDE\venv\lib\site-packages\django\db\backends\mysql\base.py", line 74, in execute
    return self.cursor.execute(query, args)
  File "D:\GIT CMS TIRPUDE\venv\lib\site-packages\MySQLdb\cursors.py", line 209, in execute
    res = self._query(query)
  File "D:\GIT CMS TIRPUDE\venv\lib\site-packages\MySQLdb\cursors.py", line 315, in _query
    db.query(q)
  File "D:\GIT CMS TIRPUDE\venv\lib\site-packages\MySQLdb\connections.py", line 239, in query
    _mysql.connection.query(self, query)
MySQLdb._exceptions.OperationalError: (1054, "Unknown column 'authentication_addressdetail.fk_district_id' in 'field list'")

The above exception was the direct cause of the following exception:

Traceback (most recent call last):
  File "D:\GIT CMS TIRPUDE\authentication\views.py", line 283, in profile_user
    address_detail_obj = AddressDetail.objects.get(fk_user_info_id=session)
  File "D:\GIT CMS TIRPUDE\venv\lib\site-packages\django\db\models\manager.py", line 82, in manager_method
    return getattr(self.get_queryset(), name)(*args, **kwargs)
  File "D:\GIT CMS TIRPUDE\venv\lib\site-packages\django\db\models\query.py", line 411, in get
    num = len(clone)
  File "D:\GIT CMS TIRPUDE\venv\lib\site-packages\django\db\models\query.py", line 258, in __len__
    self._fetch_all()
  File "D:\GIT CMS TIRPUDE\venv\lib\site-packages\django\db\models\query.py", line 1261, in _fetch_all
    self._result_cache = list(self._iterable_class(self))
  File "D:\GIT CMS TIRPUDE\venv\lib\site-packages\django\db\models\query.py", line 57, in __iter__
    results = compiler.execute_sql(chunked_fetch=self.chunked_fetch, chunk_size=self.chunk_size)
  File "D:\GIT CMS TIRPUDE\venv\lib\site-packages\django\db\models\sql\compiler.py", line 1137, in execute_sql
    cursor.execute(sql, params)
  File "D:\GIT CMS TIRPUDE\venv\lib\site-packages\django\db\backends\utils.py", line 100, in execute
    return super().execute(sql, params)
  File "D:\GIT CMS TIRPUDE\venv\lib\site-packages\django\db\backends\utils.py", line 68, in execute
    return self._execute_with_wrappers(sql, params, many=False, executor=self._execute)
  File "D:\GIT CMS TIRPUDE\venv\lib\site-packages\django\db\backends\utils.py", line 77, in _execute_with_wrappers
    return executor(sql, params, many, context)
  File "D:\GIT CMS TIRPUDE\venv\lib\site-packages\django\db\backends\utils.py", line 86, in _execute
    return self.cursor.execute(sql, params)
  File "D:\GIT CMS TIRPUDE\venv\lib\site-packages\django\db\utils.py", line 90, in __exit__
    raise dj_exc_value.with_traceback(traceback) from exc_value
  File "D:\GIT CMS TIRPUDE\venv\lib\site-packages\django\db\backends\utils.py", line 86, in _execute
    return self.cursor.execute(sql, params)
  File "D:\GIT CMS TIRPUDE\venv\lib\site-packages\django\db\backends\mysql\base.py", line 74, in execute
    return self.cursor.execute(query, args)
  File "D:\GIT CMS TIRPUDE\venv\lib\site-packages\MySQLdb\cursors.py", line 209, in execute
    res = self._query(query)
  File "D:\GIT CMS TIRPUDE\venv\lib\site-packages\MySQLdb\cursors.py", line 315, in _query
    db.query(q)
  File "D:\GIT CMS TIRPUDE\venv\lib\site-packages\MySQLdb\connections.py", line 239, in query
    _mysql.connection.query(self, query)
django.db.utils.OperationalError: (1054, "Unknown column 'authentication_addressdetail.fk_district_id' in 'field list'")


2020-01-13 13:19:04.936169
Traceback (most recent call last):
  File "D:\GIT CMS TIRPUDE\authentication\views.py", line 283, in profile_user
    address_detail_obj = AddressDetail.objects.get(fk_user_info_id=session)
  File "D:\GIT CMS TIRPUDE\venv\lib\site-packages\django\db\models\manager.py", line 82, in manager_method
    return getattr(self.get_queryset(), name)(*args, **kwargs)
  File "D:\GIT CMS TIRPUDE\venv\lib\site-packages\django\db\models\query.py", line 422, in get
    num if not limit or num < limit else 'more than %s' % (limit - 1),
authentication.models.AddressDetail.MultipleObjectsReturned: get() returned more than one AddressDetail -- it returned 3!


2020-01-13 14:45:13.405048
Traceback (most recent call last):
  File "D:\GIT CMS TIRPUDE\authentication\views.py", line 283, in profile_user
    address_detail_obj = AddressDetail.objects.get(fk_user_info_id=session)
  File "D:\GIT CMS TIRPUDE\venv\lib\site-packages\django\db\models\manager.py", line 82, in manager_method
    return getattr(self.get_queryset(), name)(*args, **kwargs)
  File "D:\GIT CMS TIRPUDE\venv\lib\site-packages\django\db\models\query.py", line 417, in get
    self.model._meta.object_name
authentication.models.AddressDetail.DoesNotExist: AddressDetail matching query does not exist.


2020-01-14 14:49:48.231061
Traceback (most recent call last):
  File "D:\GIT CMS TIRPUDE\venv\lib\site-packages\django\contrib\sessions\backends\base.py", line 199, in _get_session
    return self._session_cache
AttributeError: 'SessionStore' object has no attribute '_session_cache'

During handling of the above exception, another exception occurred:

Traceback (most recent call last):
  File "D:\GIT CMS TIRPUDE\venv\lib\site-packages\django\db\backends\base\base.py", line 220, in ensure_connection
    self.connect()
  File "D:\GIT CMS TIRPUDE\venv\lib\site-packages\django\utils\asyncio.py", line 26, in inner
    return func(*args, **kwargs)
  File "D:\GIT CMS TIRPUDE\venv\lib\site-packages\django\db\backends\base\base.py", line 197, in connect
    self.connection = self.get_new_connection(conn_params)
  File "D:\GIT CMS TIRPUDE\venv\lib\site-packages\django\utils\asyncio.py", line 26, in inner
    return func(*args, **kwargs)
  File "D:\GIT CMS TIRPUDE\venv\lib\site-packages\django\db\backends\mysql\base.py", line 233, in get_new_connection
    return Database.connect(**conn_params)
  File "D:\GIT CMS TIRPUDE\venv\lib\site-packages\MySQLdb\__init__.py", line 84, in Connect
    return Connection(*args, **kwargs)
  File "D:\GIT CMS TIRPUDE\venv\lib\site-packages\MySQLdb\connections.py", line 179, in __init__
    super(Connection, self).__init__(*args, **kwargs2)
MySQLdb._exceptions.OperationalError: (2002, "Can't connect to MySQL server on '3.6.127.100' (10060)")

The above exception was the direct cause of the following exception:

Traceback (most recent call last):
  File "D:\GIT CMS TIRPUDE\placement\views.py", line 755, in apply_visiting_company_modal_detail
    session = request.session.get('user_id')
  File "D:\GIT CMS TIRPUDE\venv\lib\site-packages\django\contrib\sessions\backends\base.py", line 75, in get
    return self._session.get(key, default)
  File "D:\GIT CMS TIRPUDE\venv\lib\site-packages\django\contrib\sessions\backends\base.py", line 204, in _get_session
    self._session_cache = self.load()
  File "D:\GIT CMS TIRPUDE\venv\lib\site-packages\django\contrib\sessions\backends\db.py", line 43, in load
    s = self._get_session_from_db()
  File "D:\GIT CMS TIRPUDE\venv\lib\site-packages\django\contrib\sessions\backends\db.py", line 34, in _get_session_from_db
    expire_date__gt=timezone.now()
  File "D:\GIT CMS TIRPUDE\venv\lib\site-packages\django\db\models\manager.py", line 82, in manager_method
    return getattr(self.get_queryset(), name)(*args, **kwargs)
  File "D:\GIT CMS TIRPUDE\venv\lib\site-packages\django\db\models\query.py", line 411, in get
    num = len(clone)
  File "D:\GIT CMS TIRPUDE\venv\lib\site-packages\django\db\models\query.py", line 258, in __len__
    self._fetch_all()
  File "D:\GIT CMS TIRPUDE\venv\lib\site-packages\django\db\models\query.py", line 1261, in _fetch_all
    self._result_cache = list(self._iterable_class(self))
  File "D:\GIT CMS TIRPUDE\venv\lib\site-packages\django\db\models\query.py", line 57, in __iter__
    results = compiler.execute_sql(chunked_fetch=self.chunked_fetch, chunk_size=self.chunk_size)
  File "D:\GIT CMS TIRPUDE\venv\lib\site-packages\django\db\models\sql\compiler.py", line 1135, in execute_sql
    cursor = self.connection.cursor()
  File "D:\GIT CMS TIRPUDE\venv\lib\site-packages\django\utils\asyncio.py", line 26, in inner
    return func(*args, **kwargs)
  File "D:\GIT CMS TIRPUDE\venv\lib\site-packages\django\db\backends\base\base.py", line 260, in cursor
    return self._cursor()
  File "D:\GIT CMS TIRPUDE\venv\lib\site-packages\django\db\backends\base\base.py", line 236, in _cursor
    self.ensure_connection()
  File "D:\GIT CMS TIRPUDE\venv\lib\site-packages\django\utils\asyncio.py", line 26, in inner
    return func(*args, **kwargs)
  File "D:\GIT CMS TIRPUDE\venv\lib\site-packages\django\db\backends\base\base.py", line 220, in ensure_connection
    self.connect()
  File "D:\GIT CMS TIRPUDE\venv\lib\site-packages\django\db\utils.py", line 90, in __exit__
    raise dj_exc_value.with_traceback(traceback) from exc_value
  File "D:\GIT CMS TIRPUDE\venv\lib\site-packages\django\db\backends\base\base.py", line 220, in ensure_connection
    self.connect()
  File "D:\GIT CMS TIRPUDE\venv\lib\site-packages\django\utils\asyncio.py", line 26, in inner
    return func(*args, **kwargs)
  File "D:\GIT CMS TIRPUDE\venv\lib\site-packages\django\db\backends\base\base.py", line 197, in connect
    self.connection = self.get_new_connection(conn_params)
  File "D:\GIT CMS TIRPUDE\venv\lib\site-packages\django\utils\asyncio.py", line 26, in inner
    return func(*args, **kwargs)
  File "D:\GIT CMS TIRPUDE\venv\lib\site-packages\django\db\backends\mysql\base.py", line 233, in get_new_connection
    return Database.connect(**conn_params)
  File "D:\GIT CMS TIRPUDE\venv\lib\site-packages\MySQLdb\__init__.py", line 84, in Connect
    return Connection(*args, **kwargs)
  File "D:\GIT CMS TIRPUDE\venv\lib\site-packages\MySQLdb\connections.py", line 179, in __init__
    super(Connection, self).__init__(*args, **kwargs2)
django.db.utils.OperationalError: (2002, "Can't connect to MySQL server on '3.6.127.100' (10060)")


2020-01-14 14:51:14.267302
Traceback (most recent call last):
  File "D:\GIT CMS TIRPUDE\venv\lib\site-packages\django\db\backends\base\base.py", line 220, in ensure_connection
    self.connect()
  File "D:\GIT CMS TIRPUDE\venv\lib\site-packages\django\utils\asyncio.py", line 26, in inner
    return func(*args, **kwargs)
  File "D:\GIT CMS TIRPUDE\venv\lib\site-packages\django\db\backends\base\base.py", line 197, in connect
    self.connection = self.get_new_connection(conn_params)
  File "D:\GIT CMS TIRPUDE\venv\lib\site-packages\django\utils\asyncio.py", line 26, in inner
    return func(*args, **kwargs)
  File "D:\GIT CMS TIRPUDE\venv\lib\site-packages\django\db\backends\mysql\base.py", line 233, in get_new_connection
    return Database.connect(**conn_params)
  File "D:\GIT CMS TIRPUDE\venv\lib\site-packages\MySQLdb\__init__.py", line 84, in Connect
    return Connection(*args, **kwargs)
  File "D:\GIT CMS TIRPUDE\venv\lib\site-packages\MySQLdb\connections.py", line 179, in __init__
    super(Connection, self).__init__(*args, **kwargs2)
MySQLdb._exceptions.OperationalError: (2002, "Can't connect to MySQL server on '3.6.127.100' (10060)")

The above exception was the direct cause of the following exception:

Traceback (most recent call last):
  File "D:\GIT CMS TIRPUDE\authentication\views.py", line 62, in get_city_district_list
    city_list = list(City.objects.filter(fk_state_id=state_id).values_list("id", "city"))
  File "D:\GIT CMS TIRPUDE\venv\lib\site-packages\django\db\models\query.py", line 276, in __iter__
    self._fetch_all()
  File "D:\GIT CMS TIRPUDE\venv\lib\site-packages\django\db\models\query.py", line 1261, in _fetch_all
    self._result_cache = list(self._iterable_class(self))
  File "D:\GIT CMS TIRPUDE\venv\lib\site-packages\django\db\models\query.py", line 146, in __iter__
    return compiler.results_iter(tuple_expected=True, chunked_fetch=self.chunked_fetch, chunk_size=self.chunk_size)
  File "D:\GIT CMS TIRPUDE\venv\lib\site-packages\django\db\models\sql\compiler.py", line 1089, in results_iter
    results = self.execute_sql(MULTI, chunked_fetch=chunked_fetch, chunk_size=chunk_size)
  File "D:\GIT CMS TIRPUDE\venv\lib\site-packages\django\db\models\sql\compiler.py", line 1135, in execute_sql
    cursor = self.connection.cursor()
  File "D:\GIT CMS TIRPUDE\venv\lib\site-packages\django\utils\asyncio.py", line 26, in inner
    return func(*args, **kwargs)
  File "D:\GIT CMS TIRPUDE\venv\lib\site-packages\django\db\backends\base\base.py", line 260, in cursor
    return self._cursor()
  File "D:\GIT CMS TIRPUDE\venv\lib\site-packages\django\db\backends\base\base.py", line 236, in _cursor
    self.ensure_connection()
  File "D:\GIT CMS TIRPUDE\venv\lib\site-packages\django\utils\asyncio.py", line 26, in inner
    return func(*args, **kwargs)
  File "D:\GIT CMS TIRPUDE\venv\lib\site-packages\django\db\backends\base\base.py", line 220, in ensure_connection
    self.connect()
  File "D:\GIT CMS TIRPUDE\venv\lib\site-packages\django\db\utils.py", line 90, in __exit__
    raise dj_exc_value.with_traceback(traceback) from exc_value
  File "D:\GIT CMS TIRPUDE\venv\lib\site-packages\django\db\backends\base\base.py", line 220, in ensure_connection
    self.connect()
  File "D:\GIT CMS TIRPUDE\venv\lib\site-packages\django\utils\asyncio.py", line 26, in inner
    return func(*args, **kwargs)
  File "D:\GIT CMS TIRPUDE\venv\lib\site-packages\django\db\backends\base\base.py", line 197, in connect
    self.connection = self.get_new_connection(conn_params)
  File "D:\GIT CMS TIRPUDE\venv\lib\site-packages\django\utils\asyncio.py", line 26, in inner
    return func(*args, **kwargs)
  File "D:\GIT CMS TIRPUDE\venv\lib\site-packages\django\db\backends\mysql\base.py", line 233, in get_new_connection
    return Database.connect(**conn_params)
  File "D:\GIT CMS TIRPUDE\venv\lib\site-packages\MySQLdb\__init__.py", line 84, in Connect
    return Connection(*args, **kwargs)
  File "D:\GIT CMS TIRPUDE\venv\lib\site-packages\MySQLdb\connections.py", line 179, in __init__
    super(Connection, self).__init__(*args, **kwargs2)
django.db.utils.OperationalError: (2002, "Can't connect to MySQL server on '3.6.127.100' (10060)")


2020-01-14 15:03:42.728208
Traceback (most recent call last):
  File "D:\GIT CMS TIRPUDE\placement\views.py", line 1484, in filter_search_student_performance
    academic_info_obj = AcademicInfo.objects.all(fk_user_info__fk_user_type__user_type="Student")
TypeError: all() got an unexpected keyword argument 'fk_user_info__fk_user_type__user_type'


2020-01-14 15:11:18.479912
Traceback (most recent call last):
  File "D:\GIT CMS TIRPUDE\placement\views.py", line 1445, in filter_search_student_performance
    academic_info_obj = eval(academic_info_obj)
  File "<string>", line 1, in <module>
AttributeError: type object 'AcademicInfo' has no attribute 'objectsfilter'


2020-01-14 15:12:34.503718
Traceback (most recent call last):
  File "D:\GIT CMS TIRPUDE\placement\views.py", line 1445, in filter_search_student_performance
    academic_info_obj = eval(academic_info_obj)
  File "<string>", line 1
    AcademicInfo.objects.filter(fk_course_id=filter_course)filter(fk_semesters__id=filter_semesters)
                                                                ^
SyntaxError: invalid syntax


2020-01-14 15:14:33.568308
Traceback (most recent call last):
  File "D:\GIT CMS TIRPUDE\placement\views.py", line 1447, in filter_search_student_performance
    {"academic_info_obj": academic_info_obj})
  File "D:\GIT CMS TIRPUDE\venv\lib\site-packages\django\template\loader.py", line 62, in render_to_string
    return template.render(context, request)
  File "D:\GIT CMS TIRPUDE\venv\lib\site-packages\django\template\backends\django.py", line 61, in render
    return self.template.render(context)
  File "D:\GIT CMS TIRPUDE\venv\lib\site-packages\django\template\base.py", line 171, in render
    return self._render(context)
  File "D:\GIT CMS TIRPUDE\venv\lib\site-packages\django\template\base.py", line 163, in _render
    return self.nodelist.render(context)
  File "D:\GIT CMS TIRPUDE\venv\lib\site-packages\django\template\base.py", line 936, in render
    bit = node.render_annotated(context)
  File "D:\GIT CMS TIRPUDE\venv\lib\site-packages\django\template\base.py", line 903, in render_annotated
    return self.render(context)
  File "D:\GIT CMS TIRPUDE\venv\lib\site-packages\django\template\defaulttags.py", line 165, in render
    values = list(values)
TypeError: 'Manager' object is not iterable


2020-01-14 15:41:23.625111
Traceback (most recent call last):
  File "D:\GIT CMS TIRPUDE\placement\views.py", line 1201, in filter_company_appearances
    if company_appearance_job_type_detail_obj:
UnboundLocalError: local variable 'company_appearance_job_type_detail_obj' referenced before assignment


2020-01-14 15:42:05.787577
Traceback (most recent call last):
  File "D:\GIT CMS TIRPUDE\placement\views.py", line 1409, in filter_company_appearances
    dict_data['company_appearance_id'] = i.id
AttributeError: 'str' object has no attribute 'id'


2020-01-14 15:43:43.539418
Traceback (most recent call last):
  File "D:\GIT CMS TIRPUDE\venv\lib\site-packages\django\db\models\fields\__init__.py", line 1768, in get_prep_value
    return int(value)
ValueError: invalid literal for int() with base 10: 'l'

The above exception was the direct cause of the following exception:

Traceback (most recent call last):
  File "D:\GIT CMS TIRPUDE\placement\views.py", line 1213, in filter_company_appearances
    company_appearance_obj = eval(company_appearance_obj)
  File "<string>", line 1, in <module>
  File "D:\GIT CMS TIRPUDE\venv\lib\site-packages\django\db\models\manager.py", line 82, in manager_method
    return getattr(self.get_queryset(), name)(*args, **kwargs)
  File "D:\GIT CMS TIRPUDE\venv\lib\site-packages\django\db\models\query.py", line 904, in filter
    return self._filter_or_exclude(False, *args, **kwargs)
  File "D:\GIT CMS TIRPUDE\venv\lib\site-packages\django\db\models\query.py", line 923, in _filter_or_exclude
    clone.query.add_q(Q(*args, **kwargs))
  File "D:\GIT CMS TIRPUDE\venv\lib\site-packages\django\db\models\sql\query.py", line 1340, in add_q
    clause, _ = self._add_q(q_object, self.used_aliases)
  File "D:\GIT CMS TIRPUDE\venv\lib\site-packages\django\db\models\sql\query.py", line 1371, in _add_q
    check_filterable=check_filterable,
  File "D:\GIT CMS TIRPUDE\venv\lib\site-packages\django\db\models\sql\query.py", line 1301, in build_filter
    condition = self.build_lookup(lookups, col, value)
  File "D:\GIT CMS TIRPUDE\venv\lib\site-packages\django\db\models\sql\query.py", line 1155, in build_lookup
    lookup = lookup_class(lhs, rhs)
  File "D:\GIT CMS TIRPUDE\venv\lib\site-packages\django\db\models\lookups.py", line 22, in __init__
    self.rhs = self.get_prep_lookup()
  File "D:\GIT CMS TIRPUDE\venv\lib\site-packages\django\db\models\fields\related_lookups.py", line 59, in get_prep_lookup
    self.rhs = [target_field.get_prep_value(v) for v in self.rhs]
  File "D:\GIT CMS TIRPUDE\venv\lib\site-packages\django\db\models\fields\related_lookups.py", line 59, in <listcomp>
    self.rhs = [target_field.get_prep_value(v) for v in self.rhs]
  File "D:\GIT CMS TIRPUDE\venv\lib\site-packages\django\db\models\fields\__init__.py", line 1772, in get_prep_value
    ) from e
ValueError: Field 'id' expected a number but got 'l'.


2020-01-14 15:44:22.257562
Traceback (most recent call last):
  File "D:\GIT CMS TIRPUDE\venv\lib\site-packages\django\db\models\fields\__init__.py", line 1768, in get_prep_value
    return int(value)
ValueError: invalid literal for int() with base 10: 'l'

The above exception was the direct cause of the following exception:

Traceback (most recent call last):
  File "D:\GIT CMS TIRPUDE\placement\views.py", line 1213, in filter_company_appearances
    company_appearance_obj = eval(company_appearance_obj)
  File "<string>", line 1, in <module>
  File "D:\GIT CMS TIRPUDE\venv\lib\site-packages\django\db\models\manager.py", line 82, in manager_method
    return getattr(self.get_queryset(), name)(*args, **kwargs)
  File "D:\GIT CMS TIRPUDE\venv\lib\site-packages\django\db\models\query.py", line 904, in filter
    return self._filter_or_exclude(False, *args, **kwargs)
  File "D:\GIT CMS TIRPUDE\venv\lib\site-packages\django\db\models\query.py", line 923, in _filter_or_exclude
    clone.query.add_q(Q(*args, **kwargs))
  File "D:\GIT CMS TIRPUDE\venv\lib\site-packages\django\db\models\sql\query.py", line 1340, in add_q
    clause, _ = self._add_q(q_object, self.used_aliases)
  File "D:\GIT CMS TIRPUDE\venv\lib\site-packages\django\db\models\sql\query.py", line 1371, in _add_q
    check_filterable=check_filterable,
  File "D:\GIT CMS TIRPUDE\venv\lib\site-packages\django\db\models\sql\query.py", line 1301, in build_filter
    condition = self.build_lookup(lookups, col, value)
  File "D:\GIT CMS TIRPUDE\venv\lib\site-packages\django\db\models\sql\query.py", line 1155, in build_lookup
    lookup = lookup_class(lhs, rhs)
  File "D:\GIT CMS TIRPUDE\venv\lib\site-packages\django\db\models\lookups.py", line 22, in __init__
    self.rhs = self.get_prep_lookup()
  File "D:\GIT CMS TIRPUDE\venv\lib\site-packages\django\db\models\fields\related_lookups.py", line 59, in get_prep_lookup
    self.rhs = [target_field.get_prep_value(v) for v in self.rhs]
  File "D:\GIT CMS TIRPUDE\venv\lib\site-packages\django\db\models\fields\related_lookups.py", line 59, in <listcomp>
    self.rhs = [target_field.get_prep_value(v) for v in self.rhs]
  File "D:\GIT CMS TIRPUDE\venv\lib\site-packages\django\db\models\fields\__init__.py", line 1772, in get_prep_value
    ) from e
ValueError: Field 'id' expected a number but got 'l'.


2020-01-14 15:45:24.417257
Traceback (most recent call last):
  File "D:\GIT CMS TIRPUDE\venv\lib\site-packages\django\db\models\fields\__init__.py", line 1768, in get_prep_value
    return int(value)
ValueError: invalid literal for int() with base 10: 'l'

The above exception was the direct cause of the following exception:

Traceback (most recent call last):
  File "D:\GIT CMS TIRPUDE\placement\views.py", line 1213, in filter_company_appearances
    company_appearance_obj = eval(company_appearance_obj)
  File "<string>", line 1, in <module>
  File "D:\GIT CMS TIRPUDE\venv\lib\site-packages\django\db\models\manager.py", line 82, in manager_method
    return getattr(self.get_queryset(), name)(*args, **kwargs)
  File "D:\GIT CMS TIRPUDE\venv\lib\site-packages\django\db\models\query.py", line 904, in filter
    return self._filter_or_exclude(False, *args, **kwargs)
  File "D:\GIT CMS TIRPUDE\venv\lib\site-packages\django\db\models\query.py", line 923, in _filter_or_exclude
    clone.query.add_q(Q(*args, **kwargs))
  File "D:\GIT CMS TIRPUDE\venv\lib\site-packages\django\db\models\sql\query.py", line 1340, in add_q
    clause, _ = self._add_q(q_object, self.used_aliases)
  File "D:\GIT CMS TIRPUDE\venv\lib\site-packages\django\db\models\sql\query.py", line 1371, in _add_q
    check_filterable=check_filterable,
  File "D:\GIT CMS TIRPUDE\venv\lib\site-packages\django\db\models\sql\query.py", line 1301, in build_filter
    condition = self.build_lookup(lookups, col, value)
  File "D:\GIT CMS TIRPUDE\venv\lib\site-packages\django\db\models\sql\query.py", line 1155, in build_lookup
    lookup = lookup_class(lhs, rhs)
  File "D:\GIT CMS TIRPUDE\venv\lib\site-packages\django\db\models\lookups.py", line 22, in __init__
    self.rhs = self.get_prep_lookup()
  File "D:\GIT CMS TIRPUDE\venv\lib\site-packages\django\db\models\fields\related_lookups.py", line 59, in get_prep_lookup
    self.rhs = [target_field.get_prep_value(v) for v in self.rhs]
  File "D:\GIT CMS TIRPUDE\venv\lib\site-packages\django\db\models\fields\related_lookups.py", line 59, in <listcomp>
    self.rhs = [target_field.get_prep_value(v) for v in self.rhs]
  File "D:\GIT CMS TIRPUDE\venv\lib\site-packages\django\db\models\fields\__init__.py", line 1772, in get_prep_value
    ) from e
ValueError: Field 'id' expected a number but got 'l'.


2020-01-14 15:48:45.256213
Traceback (most recent call last):
  File "D:\GIT CMS TIRPUDE\venv\lib\site-packages\django\db\models\fields\__init__.py", line 1768, in get_prep_value
    return int(value)
ValueError: invalid literal for int() with base 10: 'l'

The above exception was the direct cause of the following exception:

Traceback (most recent call last):
  File "D:\GIT CMS TIRPUDE\placement\views.py", line 1217, in filter_company_appearances
    company_appearance_obj = eval(company_appearance_obj)
  File "<string>", line 1, in <module>
  File "D:\GIT CMS TIRPUDE\venv\lib\site-packages\django\db\models\manager.py", line 82, in manager_method
    return getattr(self.get_queryset(), name)(*args, **kwargs)
  File "D:\GIT CMS TIRPUDE\venv\lib\site-packages\django\db\models\query.py", line 904, in filter
    return self._filter_or_exclude(False, *args, **kwargs)
  File "D:\GIT CMS TIRPUDE\venv\lib\site-packages\django\db\models\query.py", line 923, in _filter_or_exclude
    clone.query.add_q(Q(*args, **kwargs))
  File "D:\GIT CMS TIRPUDE\venv\lib\site-packages\django\db\models\sql\query.py", line 1340, in add_q
    clause, _ = self._add_q(q_object, self.used_aliases)
  File "D:\GIT CMS TIRPUDE\venv\lib\site-packages\django\db\models\sql\query.py", line 1371, in _add_q
    check_filterable=check_filterable,
  File "D:\GIT CMS TIRPUDE\venv\lib\site-packages\django\db\models\sql\query.py", line 1301, in build_filter
    condition = self.build_lookup(lookups, col, value)
  File "D:\GIT CMS TIRPUDE\venv\lib\site-packages\django\db\models\sql\query.py", line 1155, in build_lookup
    lookup = lookup_class(lhs, rhs)
  File "D:\GIT CMS TIRPUDE\venv\lib\site-packages\django\db\models\lookups.py", line 22, in __init__
    self.rhs = self.get_prep_lookup()
  File "D:\GIT CMS TIRPUDE\venv\lib\site-packages\django\db\models\fields\related_lookups.py", line 59, in get_prep_lookup
    self.rhs = [target_field.get_prep_value(v) for v in self.rhs]
  File "D:\GIT CMS TIRPUDE\venv\lib\site-packages\django\db\models\fields\related_lookups.py", line 59, in <listcomp>
    self.rhs = [target_field.get_prep_value(v) for v in self.rhs]
  File "D:\GIT CMS TIRPUDE\venv\lib\site-packages\django\db\models\fields\__init__.py", line 1772, in get_prep_value
    ) from e
ValueError: Field 'id' expected a number but got 'l'.


2020-01-14 15:52:19.486958
Traceback (most recent call last):
  File "D:\GIT CMS TIRPUDE\placement\views.py", line 1418, in filter_company_appearances
    dict_data['company_appearance_id'] = i.id
AttributeError: 'str' object has no attribute 'id'


2020-01-14 15:52:41.708392
Traceback (most recent call last):
  File "D:\GIT CMS TIRPUDE\placement\views.py", line 1418, in filter_company_appearances
    dict_data['company_appearance_id'] = i.id
AttributeError: 'str' object has no attribute 'id'


2020-01-14 15:54:59.209000
Traceback (most recent call last):
  File "D:\GIT CMS TIRPUDE\venv\lib\site-packages\django\db\models\fields\__init__.py", line 1768, in get_prep_value
    return int(value)
ValueError: invalid literal for int() with base 10: 'l'

The above exception was the direct cause of the following exception:

Traceback (most recent call last):
  File "D:\GIT CMS TIRPUDE\placement\views.py", line 1219, in filter_company_appearances
    company_appearance_obj = eval(company_appearance_obj)
  File "<string>", line 1, in <module>
  File "D:\GIT CMS TIRPUDE\venv\lib\site-packages\django\db\models\manager.py", line 82, in manager_method
    return getattr(self.get_queryset(), name)(*args, **kwargs)
  File "D:\GIT CMS TIRPUDE\venv\lib\site-packages\django\db\models\query.py", line 904, in filter
    return self._filter_or_exclude(False, *args, **kwargs)
  File "D:\GIT CMS TIRPUDE\venv\lib\site-packages\django\db\models\query.py", line 923, in _filter_or_exclude
    clone.query.add_q(Q(*args, **kwargs))
  File "D:\GIT CMS TIRPUDE\venv\lib\site-packages\django\db\models\sql\query.py", line 1340, in add_q
    clause, _ = self._add_q(q_object, self.used_aliases)
  File "D:\GIT CMS TIRPUDE\venv\lib\site-packages\django\db\models\sql\query.py", line 1371, in _add_q
    check_filterable=check_filterable,
  File "D:\GIT CMS TIRPUDE\venv\lib\site-packages\django\db\models\sql\query.py", line 1301, in build_filter
    condition = self.build_lookup(lookups, col, value)
  File "D:\GIT CMS TIRPUDE\venv\lib\site-packages\django\db\models\sql\query.py", line 1155, in build_lookup
    lookup = lookup_class(lhs, rhs)
  File "D:\GIT CMS TIRPUDE\venv\lib\site-packages\django\db\models\lookups.py", line 22, in __init__
    self.rhs = self.get_prep_lookup()
  File "D:\GIT CMS TIRPUDE\venv\lib\site-packages\django\db\models\fields\related_lookups.py", line 59, in get_prep_lookup
    self.rhs = [target_field.get_prep_value(v) for v in self.rhs]
  File "D:\GIT CMS TIRPUDE\venv\lib\site-packages\django\db\models\fields\related_lookups.py", line 59, in <listcomp>
    self.rhs = [target_field.get_prep_value(v) for v in self.rhs]
  File "D:\GIT CMS TIRPUDE\venv\lib\site-packages\django\db\models\fields\__init__.py", line 1772, in get_prep_value
    ) from e
ValueError: Field 'id' expected a number but got 'l'.


2020-01-14 15:55:13.098074
Traceback (most recent call last):
  File "D:\GIT CMS TIRPUDE\venv\lib\site-packages\django\db\models\fields\__init__.py", line 1768, in get_prep_value
    return int(value)
ValueError: invalid literal for int() with base 10: 'l'

The above exception was the direct cause of the following exception:

Traceback (most recent call last):
  File "D:\GIT CMS TIRPUDE\placement\views.py", line 1219, in filter_company_appearances
    company_appearance_obj = eval(company_appearance_obj)
  File "<string>", line 1, in <module>
  File "D:\GIT CMS TIRPUDE\venv\lib\site-packages\django\db\models\manager.py", line 82, in manager_method
    return getattr(self.get_queryset(), name)(*args, **kwargs)
  File "D:\GIT CMS TIRPUDE\venv\lib\site-packages\django\db\models\query.py", line 904, in filter
    return self._filter_or_exclude(False, *args, **kwargs)
  File "D:\GIT CMS TIRPUDE\venv\lib\site-packages\django\db\models\query.py", line 923, in _filter_or_exclude
    clone.query.add_q(Q(*args, **kwargs))
  File "D:\GIT CMS TIRPUDE\venv\lib\site-packages\django\db\models\sql\query.py", line 1340, in add_q
    clause, _ = self._add_q(q_object, self.used_aliases)
  File "D:\GIT CMS TIRPUDE\venv\lib\site-packages\django\db\models\sql\query.py", line 1371, in _add_q
    check_filterable=check_filterable,
  File "D:\GIT CMS TIRPUDE\venv\lib\site-packages\django\db\models\sql\query.py", line 1301, in build_filter
    condition = self.build_lookup(lookups, col, value)
  File "D:\GIT CMS TIRPUDE\venv\lib\site-packages\django\db\models\sql\query.py", line 1155, in build_lookup
    lookup = lookup_class(lhs, rhs)
  File "D:\GIT CMS TIRPUDE\venv\lib\site-packages\django\db\models\lookups.py", line 22, in __init__
    self.rhs = self.get_prep_lookup()
  File "D:\GIT CMS TIRPUDE\venv\lib\site-packages\django\db\models\fields\related_lookups.py", line 59, in get_prep_lookup
    self.rhs = [target_field.get_prep_value(v) for v in self.rhs]
  File "D:\GIT CMS TIRPUDE\venv\lib\site-packages\django\db\models\fields\related_lookups.py", line 59, in <listcomp>
    self.rhs = [target_field.get_prep_value(v) for v in self.rhs]
  File "D:\GIT CMS TIRPUDE\venv\lib\site-packages\django\db\models\fields\__init__.py", line 1772, in get_prep_value
    ) from e
ValueError: Field 'id' expected a number but got 'l'.


2020-01-14 15:56:09.243768
Traceback (most recent call last):
  File "D:\GIT CMS TIRPUDE\venv\lib\site-packages\django\db\models\fields\__init__.py", line 1768, in get_prep_value
    return int(value)
ValueError: invalid literal for int() with base 10: 'l'

The above exception was the direct cause of the following exception:

Traceback (most recent call last):
  File "D:\GIT CMS TIRPUDE\placement\views.py", line 1219, in filter_company_appearances
    company_appearance_obj = eval(company_appearance_obj)
  File "<string>", line 1, in <module>
  File "D:\GIT CMS TIRPUDE\venv\lib\site-packages\django\db\models\manager.py", line 82, in manager_method
    return getattr(self.get_queryset(), name)(*args, **kwargs)
  File "D:\GIT CMS TIRPUDE\venv\lib\site-packages\django\db\models\query.py", line 904, in filter
    return self._filter_or_exclude(False, *args, **kwargs)
  File "D:\GIT CMS TIRPUDE\venv\lib\site-packages\django\db\models\query.py", line 923, in _filter_or_exclude
    clone.query.add_q(Q(*args, **kwargs))
  File "D:\GIT CMS TIRPUDE\venv\lib\site-packages\django\db\models\sql\query.py", line 1340, in add_q
    clause, _ = self._add_q(q_object, self.used_aliases)
  File "D:\GIT CMS TIRPUDE\venv\lib\site-packages\django\db\models\sql\query.py", line 1371, in _add_q
    check_filterable=check_filterable,
  File "D:\GIT CMS TIRPUDE\venv\lib\site-packages\django\db\models\sql\query.py", line 1301, in build_filter
    condition = self.build_lookup(lookups, col, value)
  File "D:\GIT CMS TIRPUDE\venv\lib\site-packages\django\db\models\sql\query.py", line 1155, in build_lookup
    lookup = lookup_class(lhs, rhs)
  File "D:\GIT CMS TIRPUDE\venv\lib\site-packages\django\db\models\lookups.py", line 22, in __init__
    self.rhs = self.get_prep_lookup()
  File "D:\GIT CMS TIRPUDE\venv\lib\site-packages\django\db\models\fields\related_lookups.py", line 59, in get_prep_lookup
    self.rhs = [target_field.get_prep_value(v) for v in self.rhs]
  File "D:\GIT CMS TIRPUDE\venv\lib\site-packages\django\db\models\fields\related_lookups.py", line 59, in <listcomp>
    self.rhs = [target_field.get_prep_value(v) for v in self.rhs]
  File "D:\GIT CMS TIRPUDE\venv\lib\site-packages\django\db\models\fields\__init__.py", line 1772, in get_prep_value
    ) from e
ValueError: Field 'id' expected a number but got 'l'.


2020-01-14 15:58:19.824521
Traceback (most recent call last):
  File "D:\GIT CMS TIRPUDE\venv\lib\site-packages\django\db\models\fields\__init__.py", line 1768, in get_prep_value
    return int(value)
ValueError: invalid literal for int() with base 10: 'l'

The above exception was the direct cause of the following exception:

Traceback (most recent call last):
  File "D:\GIT CMS TIRPUDE\placement\views.py", line 1219, in filter_company_appearances
    company_appearance_obj = eval(company_appearance_obj)
  File "<string>", line 1, in <module>
  File "D:\GIT CMS TIRPUDE\venv\lib\site-packages\django\db\models\manager.py", line 82, in manager_method
    return getattr(self.get_queryset(), name)(*args, **kwargs)
  File "D:\GIT CMS TIRPUDE\venv\lib\site-packages\django\db\models\query.py", line 904, in filter
    return self._filter_or_exclude(False, *args, **kwargs)
  File "D:\GIT CMS TIRPUDE\venv\lib\site-packages\django\db\models\query.py", line 923, in _filter_or_exclude
    clone.query.add_q(Q(*args, **kwargs))
  File "D:\GIT CMS TIRPUDE\venv\lib\site-packages\django\db\models\sql\query.py", line 1340, in add_q
    clause, _ = self._add_q(q_object, self.used_aliases)
  File "D:\GIT CMS TIRPUDE\venv\lib\site-packages\django\db\models\sql\query.py", line 1371, in _add_q
    check_filterable=check_filterable,
  File "D:\GIT CMS TIRPUDE\venv\lib\site-packages\django\db\models\sql\query.py", line 1301, in build_filter
    condition = self.build_lookup(lookups, col, value)
  File "D:\GIT CMS TIRPUDE\venv\lib\site-packages\django\db\models\sql\query.py", line 1155, in build_lookup
    lookup = lookup_class(lhs, rhs)
  File "D:\GIT CMS TIRPUDE\venv\lib\site-packages\django\db\models\lookups.py", line 22, in __init__
    self.rhs = self.get_prep_lookup()
  File "D:\GIT CMS TIRPUDE\venv\lib\site-packages\django\db\models\fields\related_lookups.py", line 59, in get_prep_lookup
    self.rhs = [target_field.get_prep_value(v) for v in self.rhs]
  File "D:\GIT CMS TIRPUDE\venv\lib\site-packages\django\db\models\fields\related_lookups.py", line 59, in <listcomp>
    self.rhs = [target_field.get_prep_value(v) for v in self.rhs]
  File "D:\GIT CMS TIRPUDE\venv\lib\site-packages\django\db\models\fields\__init__.py", line 1772, in get_prep_value
    ) from e
ValueError: Field 'id' expected a number but got 'l'.


2020-01-14 15:58:42.538177
Traceback (most recent call last):
  File "D:\GIT CMS TIRPUDE\venv\lib\site-packages\django\db\models\fields\__init__.py", line 1768, in get_prep_value
    return int(value)
ValueError: invalid literal for int() with base 10: 'l'

The above exception was the direct cause of the following exception:

Traceback (most recent call last):
  File "D:\GIT CMS TIRPUDE\placement\views.py", line 1219, in filter_company_appearances
    company_appearance_obj = eval(company_appearance_obj)
  File "<string>", line 1, in <module>
  File "D:\GIT CMS TIRPUDE\venv\lib\site-packages\django\db\models\manager.py", line 82, in manager_method
    return getattr(self.get_queryset(), name)(*args, **kwargs)
  File "D:\GIT CMS TIRPUDE\venv\lib\site-packages\django\db\models\query.py", line 904, in filter
    return self._filter_or_exclude(False, *args, **kwargs)
  File "D:\GIT CMS TIRPUDE\venv\lib\site-packages\django\db\models\query.py", line 923, in _filter_or_exclude
    clone.query.add_q(Q(*args, **kwargs))
  File "D:\GIT CMS TIRPUDE\venv\lib\site-packages\django\db\models\sql\query.py", line 1340, in add_q
    clause, _ = self._add_q(q_object, self.used_aliases)
  File "D:\GIT CMS TIRPUDE\venv\lib\site-packages\django\db\models\sql\query.py", line 1371, in _add_q
    check_filterable=check_filterable,
  File "D:\GIT CMS TIRPUDE\venv\lib\site-packages\django\db\models\sql\query.py", line 1301, in build_filter
    condition = self.build_lookup(lookups, col, value)
  File "D:\GIT CMS TIRPUDE\venv\lib\site-packages\django\db\models\sql\query.py", line 1155, in build_lookup
    lookup = lookup_class(lhs, rhs)
  File "D:\GIT CMS TIRPUDE\venv\lib\site-packages\django\db\models\lookups.py", line 22, in __init__
    self.rhs = self.get_prep_lookup()
  File "D:\GIT CMS TIRPUDE\venv\lib\site-packages\django\db\models\fields\related_lookups.py", line 59, in get_prep_lookup
    self.rhs = [target_field.get_prep_value(v) for v in self.rhs]
  File "D:\GIT CMS TIRPUDE\venv\lib\site-packages\django\db\models\fields\related_lookups.py", line 59, in <listcomp>
    self.rhs = [target_field.get_prep_value(v) for v in self.rhs]
  File "D:\GIT CMS TIRPUDE\venv\lib\site-packages\django\db\models\fields\__init__.py", line 1772, in get_prep_value
    ) from e
ValueError: Field 'id' expected a number but got 'l'.


2020-01-14 16:00:25.617096
Traceback (most recent call last):
  File "D:\GIT CMS TIRPUDE\placement\views.py", line 1200, in filter_company_appearances
    company_appearance_job_type_detail_obj = list(CompanyAppearanceJobTypeDetail.objects.filter(fk_jobtype__id=filter_job_type).values_list('id',flat=True).distinct())
  File "D:\GIT CMS TIRPUDE\venv\lib\site-packages\django\db\models\manager.py", line 82, in manager_method
    return getattr(self.get_queryset(), name)(*args, **kwargs)
  File "D:\GIT CMS TIRPUDE\venv\lib\site-packages\django\db\models\query.py", line 904, in filter
    return self._filter_or_exclude(False, *args, **kwargs)
  File "D:\GIT CMS TIRPUDE\venv\lib\site-packages\django\db\models\query.py", line 923, in _filter_or_exclude
    clone.query.add_q(Q(*args, **kwargs))
  File "D:\GIT CMS TIRPUDE\venv\lib\site-packages\django\db\models\sql\query.py", line 1340, in add_q
    clause, _ = self._add_q(q_object, self.used_aliases)
  File "D:\GIT CMS TIRPUDE\venv\lib\site-packages\django\db\models\sql\query.py", line 1371, in _add_q
    check_filterable=check_filterable,
  File "D:\GIT CMS TIRPUDE\venv\lib\site-packages\django\db\models\sql\query.py", line 1240, in build_filter
    lookups, parts, reffed_expression = self.solve_lookup_type(arg)
  File "D:\GIT CMS TIRPUDE\venv\lib\site-packages\django\db\models\sql\query.py", line 1077, in solve_lookup_type
    _, field, _, lookup_parts = self.names_to_path(lookup_splitted, self.get_meta())
  File "D:\GIT CMS TIRPUDE\venv\lib\site-packages\django\db\models\sql\query.py", line 1473, in names_to_path
    "Choices are: %s" % (name, ", ".join(available)))
django.core.exceptions.FieldError: Cannot resolve keyword 'fk_jobtype' into field. Choices are: companyappearance, fk_job_type, id, job_location, package


2020-01-14 16:02:27.930367
Traceback (most recent call last):
  File "D:\GIT CMS TIRPUDE\venv\lib\site-packages\django\db\models\fields\__init__.py", line 1768, in get_prep_value
    return int(value)
ValueError: invalid literal for int() with base 10: 'l'

The above exception was the direct cause of the following exception:

Traceback (most recent call last):
  File "D:\GIT CMS TIRPUDE\placement\views.py", line 1219, in filter_company_appearances
    company_appearance_obj = eval(company_appearance_obj)
  File "<string>", line 1, in <module>
  File "D:\GIT CMS TIRPUDE\venv\lib\site-packages\django\db\models\query.py", line 904, in filter
    return self._filter_or_exclude(False, *args, **kwargs)
  File "D:\GIT CMS TIRPUDE\venv\lib\site-packages\django\db\models\query.py", line 923, in _filter_or_exclude
    clone.query.add_q(Q(*args, **kwargs))
  File "D:\GIT CMS TIRPUDE\venv\lib\site-packages\django\db\models\sql\query.py", line 1340, in add_q
    clause, _ = self._add_q(q_object, self.used_aliases)
  File "D:\GIT CMS TIRPUDE\venv\lib\site-packages\django\db\models\sql\query.py", line 1371, in _add_q
    check_filterable=check_filterable,
  File "D:\GIT CMS TIRPUDE\venv\lib\site-packages\django\db\models\sql\query.py", line 1301, in build_filter
    condition = self.build_lookup(lookups, col, value)
  File "D:\GIT CMS TIRPUDE\venv\lib\site-packages\django\db\models\sql\query.py", line 1155, in build_lookup
    lookup = lookup_class(lhs, rhs)
  File "D:\GIT CMS TIRPUDE\venv\lib\site-packages\django\db\models\lookups.py", line 22, in __init__
    self.rhs = self.get_prep_lookup()
  File "D:\GIT CMS TIRPUDE\venv\lib\site-packages\django\db\models\fields\related_lookups.py", line 59, in get_prep_lookup
    self.rhs = [target_field.get_prep_value(v) for v in self.rhs]
  File "D:\GIT CMS TIRPUDE\venv\lib\site-packages\django\db\models\fields\related_lookups.py", line 59, in <listcomp>
    self.rhs = [target_field.get_prep_value(v) for v in self.rhs]
  File "D:\GIT CMS TIRPUDE\venv\lib\site-packages\django\db\models\fields\__init__.py", line 1772, in get_prep_value
    ) from e
ValueError: Field 'id' expected a number but got 'l'.


2020-01-14 16:03:28.389070
Traceback (most recent call last):
  File "D:\GIT CMS TIRPUDE\venv\lib\site-packages\django\db\models\fields\__init__.py", line 1768, in get_prep_value
    return int(value)
ValueError: invalid literal for int() with base 10: 'l'

The above exception was the direct cause of the following exception:

Traceback (most recent call last):
  File "D:\GIT CMS TIRPUDE\placement\views.py", line 1219, in filter_company_appearances
    company_appearance_obj = eval(company_appearance_obj)
  File "<string>", line 1, in <module>
  File "D:\GIT CMS TIRPUDE\venv\lib\site-packages\django\db\models\query.py", line 904, in filter
    return self._filter_or_exclude(False, *args, **kwargs)
  File "D:\GIT CMS TIRPUDE\venv\lib\site-packages\django\db\models\query.py", line 923, in _filter_or_exclude
    clone.query.add_q(Q(*args, **kwargs))
  File "D:\GIT CMS TIRPUDE\venv\lib\site-packages\django\db\models\sql\query.py", line 1340, in add_q
    clause, _ = self._add_q(q_object, self.used_aliases)
  File "D:\GIT CMS TIRPUDE\venv\lib\site-packages\django\db\models\sql\query.py", line 1371, in _add_q
    check_filterable=check_filterable,
  File "D:\GIT CMS TIRPUDE\venv\lib\site-packages\django\db\models\sql\query.py", line 1301, in build_filter
    condition = self.build_lookup(lookups, col, value)
  File "D:\GIT CMS TIRPUDE\venv\lib\site-packages\django\db\models\sql\query.py", line 1155, in build_lookup
    lookup = lookup_class(lhs, rhs)
  File "D:\GIT CMS TIRPUDE\venv\lib\site-packages\django\db\models\lookups.py", line 22, in __init__
    self.rhs = self.get_prep_lookup()
  File "D:\GIT CMS TIRPUDE\venv\lib\site-packages\django\db\models\fields\related_lookups.py", line 59, in get_prep_lookup
    self.rhs = [target_field.get_prep_value(v) for v in self.rhs]
  File "D:\GIT CMS TIRPUDE\venv\lib\site-packages\django\db\models\fields\related_lookups.py", line 59, in <listcomp>
    self.rhs = [target_field.get_prep_value(v) for v in self.rhs]
  File "D:\GIT CMS TIRPUDE\venv\lib\site-packages\django\db\models\fields\__init__.py", line 1772, in get_prep_value
    ) from e
ValueError: Field 'id' expected a number but got 'l'.


2020-01-14 16:14:13.734104
Traceback (most recent call last):
  File "D:\GIT CMS TIRPUDE\venv\lib\site-packages\django\db\models\fields\__init__.py", line 1768, in get_prep_value
    return int(value)
ValueError: invalid literal for int() with base 10: '.'

The above exception was the direct cause of the following exception:

Traceback (most recent call last):
  File "D:\GIT CMS TIRPUDE\placement\views.py", line 1219, in filter_company_appearances
    company_appearance_obj = eval(company_appearance_obj)
  File "<string>", line 1, in <module>
  File "D:\GIT CMS TIRPUDE\venv\lib\site-packages\django\db\models\manager.py", line 82, in manager_method
    return getattr(self.get_queryset(), name)(*args, **kwargs)
  File "D:\GIT CMS TIRPUDE\venv\lib\site-packages\django\db\models\query.py", line 904, in filter
    return self._filter_or_exclude(False, *args, **kwargs)
  File "D:\GIT CMS TIRPUDE\venv\lib\site-packages\django\db\models\query.py", line 923, in _filter_or_exclude
    clone.query.add_q(Q(*args, **kwargs))
  File "D:\GIT CMS TIRPUDE\venv\lib\site-packages\django\db\models\sql\query.py", line 1340, in add_q
    clause, _ = self._add_q(q_object, self.used_aliases)
  File "D:\GIT CMS TIRPUDE\venv\lib\site-packages\django\db\models\sql\query.py", line 1371, in _add_q
    check_filterable=check_filterable,
  File "D:\GIT CMS TIRPUDE\venv\lib\site-packages\django\db\models\sql\query.py", line 1301, in build_filter
    condition = self.build_lookup(lookups, col, value)
  File "D:\GIT CMS TIRPUDE\venv\lib\site-packages\django\db\models\sql\query.py", line 1155, in build_lookup
    lookup = lookup_class(lhs, rhs)
  File "D:\GIT CMS TIRPUDE\venv\lib\site-packages\django\db\models\lookups.py", line 22, in __init__
    self.rhs = self.get_prep_lookup()
  File "D:\GIT CMS TIRPUDE\venv\lib\site-packages\django\db\models\fields\related_lookups.py", line 59, in get_prep_lookup
    self.rhs = [target_field.get_prep_value(v) for v in self.rhs]
  File "D:\GIT CMS TIRPUDE\venv\lib\site-packages\django\db\models\fields\related_lookups.py", line 59, in <listcomp>
    self.rhs = [target_field.get_prep_value(v) for v in self.rhs]
  File "D:\GIT CMS TIRPUDE\venv\lib\site-packages\django\db\models\fields\__init__.py", line 1772, in get_prep_value
    ) from e
ValueError: Field 'id' expected a number but got '.'.


2020-01-14 16:15:25.022704
Traceback (most recent call last):
  File "D:\GIT CMS TIRPUDE\venv\lib\site-packages\django\db\models\fields\__init__.py", line 1768, in get_prep_value
    return int(value)
ValueError: invalid literal for int() with base 10: 'l'

The above exception was the direct cause of the following exception:

Traceback (most recent call last):
  File "D:\GIT CMS TIRPUDE\placement\views.py", line 1217, in filter_company_appearances
    company_appearance_obj = eval(company_appearance_obj)
  File "<string>", line 1, in <module>
  File "D:\GIT CMS TIRPUDE\venv\lib\site-packages\django\db\models\manager.py", line 82, in manager_method
    return getattr(self.get_queryset(), name)(*args, **kwargs)
  File "D:\GIT CMS TIRPUDE\venv\lib\site-packages\django\db\models\query.py", line 904, in filter
    return self._filter_or_exclude(False, *args, **kwargs)
  File "D:\GIT CMS TIRPUDE\venv\lib\site-packages\django\db\models\query.py", line 923, in _filter_or_exclude
    clone.query.add_q(Q(*args, **kwargs))
  File "D:\GIT CMS TIRPUDE\venv\lib\site-packages\django\db\models\sql\query.py", line 1340, in add_q
    clause, _ = self._add_q(q_object, self.used_aliases)
  File "D:\GIT CMS TIRPUDE\venv\lib\site-packages\django\db\models\sql\query.py", line 1371, in _add_q
    check_filterable=check_filterable,
  File "D:\GIT CMS TIRPUDE\venv\lib\site-packages\django\db\models\sql\query.py", line 1301, in build_filter
    condition = self.build_lookup(lookups, col, value)
  File "D:\GIT CMS TIRPUDE\venv\lib\site-packages\django\db\models\sql\query.py", line 1155, in build_lookup
    lookup = lookup_class(lhs, rhs)
  File "D:\GIT CMS TIRPUDE\venv\lib\site-packages\django\db\models\lookups.py", line 22, in __init__
    self.rhs = self.get_prep_lookup()
  File "D:\GIT CMS TIRPUDE\venv\lib\site-packages\django\db\models\fields\related_lookups.py", line 59, in get_prep_lookup
    self.rhs = [target_field.get_prep_value(v) for v in self.rhs]
  File "D:\GIT CMS TIRPUDE\venv\lib\site-packages\django\db\models\fields\related_lookups.py", line 59, in <listcomp>
    self.rhs = [target_field.get_prep_value(v) for v in self.rhs]
  File "D:\GIT CMS TIRPUDE\venv\lib\site-packages\django\db\models\fields\__init__.py", line 1772, in get_prep_value
    ) from e
ValueError: Field 'id' expected a number but got 'l'.


2020-01-14 16:17:14.394011
Traceback (most recent call last):
  File "D:\GIT CMS TIRPUDE\venv\lib\site-packages\django\db\models\fields\__init__.py", line 1768, in get_prep_value
    return int(value)
ValueError: invalid literal for int() with base 10: 'C'

The above exception was the direct cause of the following exception:

Traceback (most recent call last):
  File "D:\GIT CMS TIRPUDE\placement\views.py", line 1217, in filter_company_appearances
    company_appearance_obj = eval(company_appearance_obj)
  File "<string>", line 1, in <module>
  File "D:\GIT CMS TIRPUDE\venv\lib\site-packages\django\db\models\manager.py", line 82, in manager_method
    return getattr(self.get_queryset(), name)(*args, **kwargs)
  File "D:\GIT CMS TIRPUDE\venv\lib\site-packages\django\db\models\query.py", line 904, in filter
    return self._filter_or_exclude(False, *args, **kwargs)
  File "D:\GIT CMS TIRPUDE\venv\lib\site-packages\django\db\models\query.py", line 923, in _filter_or_exclude
    clone.query.add_q(Q(*args, **kwargs))
  File "D:\GIT CMS TIRPUDE\venv\lib\site-packages\django\db\models\sql\query.py", line 1340, in add_q
    clause, _ = self._add_q(q_object, self.used_aliases)
  File "D:\GIT CMS TIRPUDE\venv\lib\site-packages\django\db\models\sql\query.py", line 1371, in _add_q
    check_filterable=check_filterable,
  File "D:\GIT CMS TIRPUDE\venv\lib\site-packages\django\db\models\sql\query.py", line 1301, in build_filter
    condition = self.build_lookup(lookups, col, value)
  File "D:\GIT CMS TIRPUDE\venv\lib\site-packages\django\db\models\sql\query.py", line 1155, in build_lookup
    lookup = lookup_class(lhs, rhs)
  File "D:\GIT CMS TIRPUDE\venv\lib\site-packages\django\db\models\lookups.py", line 22, in __init__
    self.rhs = self.get_prep_lookup()
  File "D:\GIT CMS TIRPUDE\venv\lib\site-packages\django\db\models\fields\related_lookups.py", line 59, in get_prep_lookup
    self.rhs = [target_field.get_prep_value(v) for v in self.rhs]
  File "D:\GIT CMS TIRPUDE\venv\lib\site-packages\django\db\models\fields\related_lookups.py", line 59, in <listcomp>
    self.rhs = [target_field.get_prep_value(v) for v in self.rhs]
  File "D:\GIT CMS TIRPUDE\venv\lib\site-packages\django\db\models\fields\__init__.py", line 1772, in get_prep_value
    ) from e
ValueError: Field 'id' expected a number but got 'C'.


2020-01-14 16:32:02.323823
Traceback (most recent call last):
  File "D:\GIT CMS TIRPUDE\placement\views.py", line 1252, in filter_company_appearances
    company_obj = eval(company_obj)
TypeError: eval() arg 1 must be a string, bytes or code object


2020-01-14 16:42:23.722001
Traceback (most recent call last):
  File "D:\GIT CMS TIRPUDE\placement\views.py", line 1202, in filter_company_appearances
    if company_appearance_job_type_detail_obj:
UnboundLocalError: local variable 'company_appearance_job_type_detail_obj' referenced before assignment


2020-01-14 16:42:48.287268
Traceback (most recent call last):
  File "D:\GIT CMS TIRPUDE\placement\views.py", line 1202, in filter_company_appearances
    if company_appearance_job_type_detail_obj:
UnboundLocalError: local variable 'company_appearance_job_type_detail_obj' referenced before assignment


2020-01-14 17:13:30.353662
Traceback (most recent call last):
  File "D:\GIT CMS TIRPUDE\authenticate_user\views.py", line 119, in filter_authenticate_user
    user_info_detail_obj = eval(user_info_detail_obj)
  File "<string>", line 1
    .filter(registration_date=to_date)
    ^
SyntaxError: invalid syntax


